2025-09-02 13:52:15,468 INFO    MainThread:130341 [wandb_init.py:setup_run_log_directory():686] Logging user logs to /data/user/bsindala/PhD/Research/LLM_Anomaly_Detection/wandb/run-20250902_135215-agjyvndl/logs/debug.log
2025-09-02 13:52:15,469 INFO    MainThread:130341 [wandb_init.py:setup_run_log_directory():687] Logging internal logs to /data/user/bsindala/PhD/Research/LLM_Anomaly_Detection/wandb/run-20250902_135215-agjyvndl/logs/debug-internal.log
2025-09-02 13:52:15,469 INFO    MainThread:130341 [wandb_init.py:monkeypatch_ipython():605] configuring jupyter hooks <wandb.sdk.wandb_init._WandbInit object at 0x2aac2d038490>
2025-09-02 13:52:15,469 INFO    MainThread:130341 [wandb_init.py:init():813] calling init triggers
2025-09-02 13:52:15,469 INFO    MainThread:130341 [wandb_init.py:init():818] wandb.init called with sweep_config: {}
config: {'model_name': 'roberta-base', 'num_epochs': 3, 'batch_size': 8, 'learning_rate': 1e-05, 'max_seq_length': 256, 'class_config': 2, 'sample_frac': 0.2, '_wandb': {}}
2025-09-02 13:52:16,003 INFO    MainThread:130341 [wandb_init.py:init():854] starting backend
2025-09-02 13:52:16,003 INFO    MainThread:130341 [wandb_init.py:init():857] sending inform_init request
2025-09-02 13:52:16,004 INFO    MainThread:130341 [wandb_init.py:init():865] backend started and connected
2025-09-02 13:52:16,005 INFO    MainThread:130341 [wandb_run.py:_label_probe_notebook():1318] probe notebook
2025-09-02 13:52:16,005 INFO    MainThread:130341 [wandb_run.py:_label_probe_notebook():1328] Unable to probe notebook: 'NoneType' object has no attribute 'get'
2025-09-02 13:52:16,005 INFO    MainThread:130341 [wandb_init.py:init():936] updated telemetry
2025-09-02 13:52:16,023 INFO    MainThread:130341 [wandb_init.py:init():960] communicating run to backend with 90.0 second timeout
2025-09-02 13:52:16,372 INFO    MainThread:130341 [wandb_init.py:init():1011] starting run threads in backend
2025-09-02 13:52:16,497 INFO    MainThread:130341 [wandb_run.py:_console_start():2494] atexit reg
2025-09-02 13:52:16,497 INFO    MainThread:130341 [wandb_run.py:_redirect():2342] redirect: wrap_raw
2025-09-02 13:52:16,497 INFO    MainThread:130341 [wandb_run.py:_redirect():2411] Wrapping output streams.
2025-09-02 13:52:16,498 INFO    MainThread:130341 [wandb_run.py:_redirect():2434] Redirects installed.
2025-09-02 13:52:16,498 INFO    MainThread:130341 [wandb_init.py:init():1057] run started, returning control to user process
2025-09-02 14:42:30,766 INFO    MainThread:130341 [wandb_init.py:_post_run_cell_hook():575] [no run ID] resuming backend
2025-09-02 14:46:48,620 ERROR   wandb-AsyncioManager-main:130341 [asyncio_manager.py:fn_wrap_exceptions():183] Uncaught exception in run_soon callback.
Traceback (most recent call last):
  File "/home/bsindala/.conda/envs/anomalyenv_v310/lib/python3.10/site-packages/wandb/sdk/lib/asyncio_manager.py", line 181, in fn_wrap_exceptions
    await fn()
  File "/home/bsindala/.conda/envs/anomalyenv_v310/lib/python3.10/site-packages/wandb/sdk/lib/service/service_client.py", line 65, in _send_server_request
    await self._writer.drain()
  File "/home/bsindala/.conda/envs/anomalyenv_v310/lib/python3.10/asyncio/streams.py", line 371, in drain
    await self._protocol._drain_helper()
  File "/home/bsindala/.conda/envs/anomalyenv_v310/lib/python3.10/asyncio/streams.py", line 167, in _drain_helper
    raise ConnectionResetError('Connection lost')
ConnectionResetError: Connection lost
